Workbook

Sheet Theo dõi Ngày
A1: BẢNG THEO DÕI NGÔI SAO TÍCH CỰC - LỚP 10A1 - THÁNG 3/2026
A2: STT | B2: Họ và Tên | C2: Ngày 1 | D2: Ngày 2 | E2: Ngày 3 | F2: Ngày 4 | G2: Ngày 5 | H2: Ngày 6 | I2: Ngày 7 | J2: Ngày 8 | K2: Ngày 9 | L2: Ngày 10 | M2: Ngày 11 | N2: Ngày 12 | O2: Ngày 13 | P2: Ngày 14 | Q2: Ngày 15 | R2: Ngày 16 | S2: Ngày 17 | T2: Ngày 18 | U2: Ngày 19 | V2: Ngày 20 | W2: Ngày 21 | X2: Ngày 22 | Y2: Ngày 23 | Z2: Ngày 24 | AA2: Ngày 25 | AB2: Ngày 26 | AC2: Ngày 27 | AD2: Ngày 28 | AE2: Ngày 29 | AF2: Ngày 30 | AG2: Tổng Tháng | AH2: Ghi chú
A3: 1 | B3: Lê Văn C | C3: 8 | D3: 3 | E3: 3 | F3: 8 | G3: 5 | H3: 4 | I3: 4 | J3: 4 | K3: 8 | L3: 3 | M3: 8 | N3: 8 | O3: 7 | P3: 3 | Q3: 7 | R3: 6 | S3: 3 | T3: 3 | U3: 3 | V3: 4 | W3: 4 | X3: 7 | Y3: 7 | Z3: 3 | AA3: 7 | AB3: 4 | AC3: 8 | AD3: 8 | AE3: 8 | AF3: 7 | AG3: =SUM(C3:AF3) -> 165 | AH3: Tiến bộ rõ rệt
A4: 2 | B4: Nguyễn Văn A | C4: 4 | D4: 6 | E4: 7 | F4: 5 | G4: 3 | H4: 4 | I4: 8 | J4: 6 | K4: 5 | L4: 5 | M4: 4 | N4: 4 | O4: 5 | P4: 3 | Q4: 3 | R4: 6 | S4: 3 | T4: 5 | U4: 5 | V4: 7 | W4: 5 | X4: 3 | Y4: 8 | Z4: 6 | AA4: 7 | AB4: 3 | AC4: 6 | AD4: 3 | AE4: 7 | AF4: 5 | AG4: =SUM(C4:AF4) -> 151
A5: 3 | B5: Trần Minh D | C5: 8 | D5: 7 | E5: 5 | F5: 7 | G5: 4 | H5: 8 | I5: 3 | J5: 3 | K5: 8 | L5: 4 | M5: 5 | N5: 3 | O5: 4 | P5: 3 | Q5: 6 | R5: 5 | S5: 6 | T5: 8 | U5: 5 | V5: 4 | W5: 5 | X5: 5 | Y5: 4 | Z5: 8 | AA5: 5 | AB5: 8 | AC5: 8 | AD5: 8 | AE5: 3 | AF5: 7 | AG5: =SUM(C5:AF5) -> 167 | AH5: Cần chú ý
A6: 4 | B6: Phạm Thị E | C6: 4 | D6: 7 | E6: 8 | F6: 4 | G6: 4 | H6: 6 | I6: 6 | J6: 5 | K6: 8 | L6: 8 | M6: 7 | N6: 4 | O6: 8 | P6: 5 | Q6: 3 | R6: 4 | S6: 3 | T6: 5 | U6: 6 | V6: 5 | W6: 3 | X6: 4 | Y6: 7 | Z6: 8 | AA6: 5 | AB6: 4 | AC6: 8 | AD6: 6 | AE6: 6 | AF6: 8 | AG6: =SUM(C6:AF6) -> 169 | AH6: Tiến bộ rõ rệt
A7: 5 | B7: Hoàng Văn F | C7: 4 | D7: 5 | E7: 4 | F7: 4 | G7: 8 | H7: 7 | I7: 7 | J7: 5 | K7: 8 | L7: 7 | M7: 6 | N7: 7 | O7: 6 | P7: 5 | Q7: 4 | R7: 4 | S7: 7 | T7: 6 | U7: 3 | V7: 3 | W7: 3 | X7: 4 | Y7: 8 | Z7: 4 | AA7: 8 | AB7: 6 | AC7: 7 | AD7: 3 | AE7: 6 | AF7: 6 | AG7: =SUM(C7:AF7) -> 165 | AH7: Ổn định
A8: 6 | B8: Đỗ Thị G | C8: 5 | D8: 6 | E8: 4 | F8: 6 | G8: 2 | H8: 2 | I8: 6 | J8: 4 | K8: 4 | L8: 2 | M8: 4 | N8: 5 | O8: 3 | P8: 5 | Q8: 2 | R8: 4 | S8: 6 | T8: 3 | U8: 6 | V8: 2 | W8: 4 | X8: 6 | Y8: 6 | Z8: 3 | AA8: 3 | AB8: 4 | AC8: 3 | AD8: 6 | AE8: 6 | AF8: 2 | AG8: =SUM(C8:AF8) -> 124 | AH8: Ổn định
A9: 7 | B9: Vũ Văn H | C9: 4 | D9: 5 | E9: 2 | F9: 2 | G9: 4 | H9: 4 | I9: 3 | J9: 2 | K9: 3 | L9: 6 | M9: 2 | N9: 2 | O9: 5 | P9: 2 | Q9: 6 | R9: 3 | S9: 3 | T9: 5 | U9: 6 | V9: 3 | W9: 4 | X9: 6 | Y9: 6 | Z9: 5 | AA9: 3 | AB9: 6 | AC9: 3 | AD9: 4 | AE9: 5 | AF9: 4 | AG9: =SUM(C9:AF9) -> 118 | AH9: Tiến bộ rõ rệt
A10: 8 | B10: Bùi Thị I | C10: 6 | D10: 5 | E10: 2 | F10: 3 | G10: 3 | H10: 2 | I10: 4 | J10: 2 | K10: 6 | L10: 6 | M10: 3 | N10: 6 | O10: 3 | P10: 2 | Q10: 2 | R10: 2 | S10: 3 | T10: 2 | U10: 2 | V10: 4 | W10: 2 | X10: 6 | Y10: 3 | Z10: 4 | AA10: 5 | AB10: 3 | AC10: 6 | AD10: 3 | AE10: 6 | AF10: 6 | AG10: =SUM(C10:AF10) -> 112 | AH10: Tiến bộ rõ rệt
A11: 9 | B11: Ngô Văn K | C11: 3 | D11: 5 | E11: 5 | F11: 3 | G11: 2 | H11: 2 | I11: 5 | J11: 4 | K11: 5 | L11: 5 | M11: 5 | N11: 2 | O11: 2 | P11: 2 | Q11: 5 | R11: 4 | S11: 2 | T11: 3 | U11: 3 | V11: 3 | W11: 6 | X11: 5 | Y11: 3 | Z11: 5 | AA11: 3 | AB11: 4 | AC11: 5 | AD11: 3 | AE11: 2 | AF11: 5 | AG11: =SUM(C11:AF11) -> 111
A12: 10 | B12: Đặng Thị L | C12: 6 | D12: 2 | E12: 2 | F12: 6 | G12: 2 | H12: 2 | I12: 3 | J12: 3 | K12: 5 | L12: 5 | M12: 5 | N12: 3 | O12: 5 | P12: 2 | Q12: 3 | R12: 5 | S12: 2 | T12: 5 | U12: 4 | V12: 5 | W12: 4 | X12: 5 | Y12: 6 | Z12: 5 | AA12: 3 | AB12: 3 | AC12: 4 | AD12: 3 | AE12: 2 | AF12: 6 | AG12: =SUM(C12:AF12) -> 116 | AH12: Cần chú ý
A13: 11 | B13: Lý Văn M | C13: 6 | D13: 2 | E13: 4 | F13: 2 | G13: 2 | H13: 6 | I13: 5 | J13: 6 | K13: 6 | L13: 3 | M13: 2 | N13: 6 | O13: 2 | P13: 3 | Q13: 2 | R13: 6 | S13: 2 | T13: 3 | U13: 5 | V13: 2 | W13: 6 | X13: 3 | Y13: 6 | Z13: 6 | AA13: 2 | AB13: 6 | AC13: 2 | AD13: 5 | AE13: 6 | AF13: 6 | AG13: =SUM(C13:AF13) -> 123 | AH13: Ổn định
A14: 12 | B14: Phan Thị N | C14: 4 | D14: 4 | E14: 3 | F14: 4 | G14: 3 | H14: 4 | I14: 5 | J14: 3 | K14: 4 | L14: 5 | M14: 4 | N14: 2 | O14: 2 | P14: 5 | Q14: 6 | R14: 6 | S14: 2 | T14: 2 | U14: 6 | V14: 3 | W14: 6 | X14: 4 | Y14: 3 | Z14: 4 | AA14: 2 | AB14: 3 | AC14: 4 | AD14: 4 | AE14: 3 | AF14: 5 | AG14: =SUM(C14:AF14) -> 115
A15: 13 | B15: Đinh Văn O | C15: 6 | D15: 4 | E15: 6 | F15: 6 | G15: 2 | H15: 6 | I15: 4 | J15: 2 | K15: 3 | L15: 4 | M15: 2 | N15: 2 | O15: 6 | P15: 3 | Q15: 4 | R15: 4 | S15: 6 | T15: 3 | U15: 4 | V15: 3 | W15: 4 | X15: 6 | Y15: 5 | Z15: 4 | AA15: 2 | AB15: 2 | AC15: 5 | AD15: 4 | AE15: 2 | AF15: 2 | AG15: =SUM(C15:AF15) -> 116 | AH15: Xuất sắc
A16: 14 | B16: Hồ Thị P | C16: 3 | D16: 4 | E16: 3 | F16: 5 | G16: 6 | H16: 5 | I16: 6 | J16: 2 | K16: 2 | L16: 2 | M16: 3 | N16: 6 | O16: 2 | P16: 4 | Q16: 6 | R16: 6 | S16: 3 | T16: 5 | U16: 3 | V16: 2 | W16: 4 | X16: 4 | Y16: 2 | Z16: 4 | AA16: 3 | AB16: 3 | AC16: 2 | AD16: 4 | AE16: 6 | AF16: 5 | AG16: =SUM(C16:AF16) -> 115 | AH16: Ổn định
A17: 15 | B17: Trần Thị B | C17: 3 | D17: 3 | E17: 3 | F17: 3 | G17: 5 | H17: 2 | I17: 3 | J17: 4 | K17: 5 | L17: 3 | M17: 4 | N17: 3 | O17: 2 | P17: 5 | Q17: 2 | R17: 5 | S17: 3 | T17: 3 | U17: 5 | V17: 4 | W17: 4 | X17: 3 | Y17: 3 | Z17: 2 | AA17: 3 | AB17: 5 | AC17: 4 | AD17: 4 | AE17: 2 | AF17: 4 | AG17: =SUM(C17:AF17) -> 104 | AH17: Xuất sắc
A18: 16 | B18: Mai Văn Q | C18: 6 | D18: 5 | E18: 6 | F18: 4 | G18: 2 | H18: 2 | I18: 4 | J18: 3 | K18: 6 | L18: 4 | M18: 2 | N18: 2 | O18: 6 | P18: 5 | Q18: 4 | R18: 4 | S18: 5 | T18: 6 | U18: 6 | V18: 2 | W18: 5 | X18: 6 | Y18: 3 | Z18: 4 | AA18: 2 | AB18: 5 | AC18: 2 | AD18: 6 | AE18: 6 | AF18: 3 | AG18: =SUM(C18:AF18) -> 126 | AH18: Xuất sắc
A19: 17 | B19: Dương Thị R | C19: 5 | D19: 2 | E19: 4 | F19: 6 | G19: 4 | H19: 2 | I19: 4 | J19: 6 | K19: 4 | L19: 5 | M19: 4 | N19: 5 | O19: 4 | P19: 4 | Q19: 4 | R19: 4 | S19: 4 | T19: 4 | U19: 4 | V19: 4 | W19: 4 | X19: 4 | Y19: 4 | Z19: 4 | AA19: 4 | AB19: 4 | AC19: 4 | AD19: 4 | AE19: 4 | AF19: 4 | AG19: =SUM(C19:AF19) -> 123 | AH19: Ổn định
A20: 18 | B20: Tô Văn S | C20: 4 | D20: 5 | E20: 5 | F20: 5 | G20: 3 | H20: 6 | I20: 5 | J20: 3 | K20: 2 | L20: 4 | M20: 6 | N20: 6 | O20: 4 | P20: 2 | Q20: 3 | R20: 4 | S20: 3 | T20: 3 | U20: 3 | V20: 2 | W20: 2 | X20: 3 | Y20: 5 | Z20: 6 | AA20: 2 | AB20: 5 | AC20: 5 | AD20: 6 | AE20: 3 | AF20: 5 | AG20: =SUM(C20:AF20) -> 120 | AH20: Tiến bộ rõ rệt
A21: 19 | B21: Châu Thị T | C21: 5 | D21: 3 | E21: 3 | F21: 2 | G21: 2 | H21: 5 | I21: 3 | J21: 3 | K21: 6 | L21: 5 | M21: 2 | N21: 6 | O21: 3 | P21: 2 | Q21: 5 | R21: 3 | S21: 5 | T21: 6 | U21: 6 | V21: 6 | W21: 4 | X21: 5 | Y21: 6 | Z21: 6 | AA21: 5 | AB21: 6 | AC21: 5 | AD21: 3 | AE21: 5 | AF21: 5 | AG21: =SUM(C21:AF21) -> 131 | AH21: Xuất sắc
A22: 20 | B22: Lâm Văn U | C22: 3 | D22: 4 | E22: 6 | F22: 5 | G22: 3 | H22: 4 | I22: 5 | J22: 2 | K22: 4 | L22: 3 | M22: 4 | N22: 4 | O22: 4 | P22: 6 | Q22: 2 | R22: 3 | S22: 3 | T22: 3 | U22: 5 | V22: 3 | W22: 3 | X22: 2 | Y22: 5 | Z22: 5 | AA22: 4 | AB22: 6 | AC22: 5 | AD22: 5 | AE22: 2 | AF22: 3 | AG22: =SUM(C22:AF22) -> 116
A23: 21 | B23: Cao Thị V | C23: 5 | D23: 5 | E23: 6 | F23: 2 | G23: 6 | H23: 5 | I23: 5 | J23: 2 | K23: 4 | L23: 4 | M23: 5 | N23: 5 | O23: 6 | P23: 6 | Q23: 6 | R23: 3 | S23: 5 | T23: 3 | U23: 4 | V23: 5 | W23: 5 | X23: 2 | Y23: 5 | Z23: 4 | AA23: 5 | AB23: 3 | AC23: 5 | AD23: 3 | AE23: 6 | AF23: 6 | AG23: =SUM(C23:AF23) -> 136 | AH23: Tích cực
A24: 22 | B24: Trịnh Văn W | C24: 5 | D24: 6 | E24: 6 | F24: 2 | G24: 2 | H24: 5 | I24: 3 | J24: 5 | K24: 3 | L24: 2 | M24: 4 | N24: 5 | O24: 4 | P24: 3 | Q24: 5 | R24: 4 | S24: 4 | T24: 5 | U24: 4 | V24: 5 | W24: 4 | X24: 2 | Y24: 5 | Z24: 2 | AA24: 6 | AB24: 2 | AC24: 4 | AD24: 3 | AE24: 2 | AF24: 2 | AG24: =SUM(C24:AF24) -> 114
A25: 23 | B25: Từ Thị X | C25: 2 | D25: 3 | E25: 3 | F25: 2 | G25: 6 | H25: 3 | I25: 3 | J25: 3 | K25: 5 | L25: 2 | M25: 6 | N25: 3 | O25: 5 | P25: 4 | Q25: 4 | R25: 3 | S25: 6 | T25: 6 | U25: 2 | V25: 3 | W25: 4 | X25: 2 | Y25: 6 | Z25: 2 | AA25: 4 | AB25: 6 | AC25: 5 | AD25: 5 | AE25: 3 | AF25: 2 | AG25: =SUM(C25:AF25) -> 113 | AH25: Ổn định
A26: 24 | B26: Huỳnh Văn Y | C26: 3 | D26: 2 | E26: 4 | F26: 6 | G26: 2 | H26: 6 | I26: 2 | J26: 4 | K26: 6 | L26: 5 | M26: 4 | N26: 2 | O26: 6 | P26: 4 | Q26: 2 | R26: 5 | S26: 5 | T26: 2 | U26: 5 | V26: 4 | W26: 5 | X26: 3 | Y26: 5 | Z26: 3 | AA26: 6 | AB26: 4 | AC26: 6 | AD26: 6 | AE26: 5 | AF26: 5 | AG26: =SUM(C26:AF26) -> 127 | AH26: Tiến bộ rõ rệt
A27: 25 | B27: Võ Thị Z | C27: 6 | D27: 4 | E27: 4 | F27: 3 | G27: 2 | H27: 4 | I27: 5 | J27: 3 | K27: 5 | L27: 6 | M27: 6 | N27: 5 | O27: 4 | P27: 2 | Q27: 5 | R27: 4 | S27: 3 | T27: 5 | U27: 3 | V27: 4 | W27: 4 | X27: 4 | Y27: 4 | Z27: 6 | AA27: 4 | AB27: 6 | AC27: 2 | AD27: 6 | AE27: 3 | AF27: 2 | AG27: =SUM(C27:AF27) -> 124 | AH27: Cần động viên
A28: 26 | B28: Nguyễn Minh AA | C28: 4 | D28: 4 | E28: 2 | F28: 4 | G28: 4 | H28: 4 | I28: 1 | J28: 1 | K28: 3 | L28: 2 | M28: 4 | N28: 2 | O28: 3 | P28: 3 | Q28: 4 | R28: 3 | S28: 4 | T28: 3 | U28: 3 | V28: 4 | W28: 3 | X28: 3 | Y28: 3 | Z28: 2 | AA28: 1 | AB28: 2 | AC28: 3 | AD28: 1 | AE28: 2 | AF28: 2 | AG28: =SUM(C28:AF28) -> 84 | AH28: Cần động viên
A29: 27 | B29: Trần Văn AB | C29: 4 | D29: 3 | E29: 3 | F29: 1 | G29: 2 | H29: 3 | I29: 2 | J29: 3 | K29: 2 | L29: 3 | M29: 1 | N29: 2 | O29: 3 | P29: 1 | Q29: 1 | R29: 3 | S29: 2 | T29: 4 | U29: 1 | V29: 1 | W29: 3 | X29: 4 | Y29: 4 | Z29: 4 | AA29: 3 | AB29: 2 | AC29: 1 | AD29: 3 | AE29: 4 | AF29: 1 | AG29: =SUM(C29:AF29) -> 74
A30: 28 | B30: Lê Thị AC | C30: 1 | D30: 4 | E30: 4 | F30: 1 | G30: 1 | H30: 2 | I30: 2 | J30: 3 | K30: 1 | L30: 2 | M30: 1 | N30: 4 | O30: 2 | P30: 4 | Q30: 4 | R30: 4 | S30: 3 | T30: 4 | U30: 3 | V30: 1 | W30: 1 | X30: 2 | Y30: 2 | Z30: 3 | AA30: 1 | AB30: 2 | AC30: 2 | AD30: 2 | AE30: 1 | AF30: 2 | AG30: =SUM(C30:AF30) -> 69 | AH30: Tích cực
A31: 29 | B31: Phạm Văn AD | C31: 4 | D31: 4 | E31: 4 | F31: 3 | G31: 1 | H31: 2 | I31: 3 | J31: 3 | K31: 4 | L31: 1 | M31: 2 | N31: 3 | O31: 2 | P31: 4 | Q31: 1 | R31: 2 | S31: 2 | T31: 3 | U31: 2 | V31: 1 | W31: 1 | X31: 2 | Y31: 3 | Z31: 3 | AA31: 4 | AB31: 1 | AC31: 4 | AD31: 3 | AE31: 4 | AF31: 3 | AG31: =SUM(C31:AF31) -> 79 | AH31: Ổn định
A32: 30 | B32: Hoàng Thị AE | C32: 4 | D32: 4 | E32: 1 | F32: 1 | G32: 4 | H32: 3 | I32: 3 | J32: 1 | K32: 1 | L32: 2 | M32: 1 | N32: 3 | O32: 1 | P32: 2 | Q32: 4 | R32: 4 | S32: 3 | T32: 2 | U32: 4 | V32: 4 | W32: 1 | X32: 4 | Y32: 3 | Z32: 4 | AA32: 3 | AB32: 3 | AC32: 1 | AD32: 2 | AE32: 3 | AF32: 4 | AG32: =SUM(C32:AF32) -> 80 | AH32: Cần chú ý
A33: 31 | B33: Đỗ Văn AF | C33: 4 | D33: 3 | E33: 4 | F33: 1 | G33: 4 | H33: 1 | I33: 3 | J33: 3 | K33: 3 | L33: 1 | M33: 4 | N33: 1 | O33: 4 | P33: 4 | Q33: 1 | R33: 2 | S33: 3 | T33: 4 | U33: 4 | V33: 1 | W33: 2 | X33: 3 | Y33: 2 | Z33: 3 | AA33: 4 | AB33: 4 | AC33: 1 | AD33: 1 | AE33: 2 | AF33: 2 | AG33: =SUM(C33:AF33) -> 79 | AH33: Xuất sắc
A34: 32 | B34: Vũ Thị AG | C34: 1 | D34: 4 | E34: 1 | F34: 2 | G34: 1 | H34: 4 | I34: 1 | J34: 2 | K34: 4 | L34: 3 | M34: 3 | N34: 4 | O34: 4 | P34: 4 | Q34: 2 | R34: 4 | S34: 2 | T34: 4 | U34: 2 | V34: 2 | W34: 1 | X34: 3 | Y34: 4 | Z34: 3 | AA34: 3 | AB34: 1 | AC34: 3 | AD34: 3 | AE34: 4 | AF34: 2 | AG34: =SUM(C34:AF34) -> 81 | AH34: Tiến bộ rõ rệt
A35: 33 | B35: Bùi Văn AH | C35: 4 | D35: 3 | E35: 3 | F35: 4 | G35: 4 | H35: 3 | I35: 2 | J35: 2 | K35: 4 | L35: 2 | M35: 4 | N35: 1 | O35: 3 | P35: 4 | Q35: 4 | R35: 4 | S35: 2 | T35: 4 | U35: 1 | V35: 2 | W35: 3 | X35: 1 | Y35: 4 | Z35: 1 | AA35: 4 | AB35: 1 | AC35: 2 | AD35: 4 | AE35: 2 | AF35: 1 | AG35: =SUM(C35:AF35) -> 83 | AH35: Tiến bộ rõ rệt
A36: 34 | B36: Ngô Thị AI | C36: 3 | D36: 3 | E36: 4 | F36: 1 | G36: 3 | H36: 4 | I36: 3 | J36: 4 | K36: 1 | L36: 1 | M36: 2 | N36: 3 | O36: 2 | P36: 1 | Q36: 4 | R36: 1 | S36: 1 | T36: 4 | U36: 2 | V36: 3 | W36: 1 | X36: 1 | Y36: 3 | Z36: 1 | AA36: 3 | AB36: 3 | AC36: 3 | AD36: 4 | AE36: 2 | AF36: 2 | AG36: =SUM(C36:AF36) -> 73 | AH36: Ổn định
A37: 35 | B37: Phạm Văn D | C37: 4 | D37: 2 | E37: 2 | F37: 2 | G37: 1 | H37: 4 | I37: 2 | J37: 4 | K37: 2 | L37: 2 | M37: 4 | N37: 3 | O37: 4 | P37: 4 | Q37: 4 | R37: 4 | S37: 4 | T37: 4 | U37: 4 | V37: 4 | W37: 4 | X37: 4 | Y37: 4 | Z37: 4 | AA37: 4 | AB37: 4 | AC37: 4 | AD37: 4 | AE37: 4 | AF37: 4 | AG37: =SUM(C37:AF37) -> 104 | AH37: Cần động viên
A38: 36 | B38: Đặng Văn AK | C38: 3 | D38: 2 | E38: 2 | F38: 2 | G38: 0 | H38: 3 | I38: 2 | J38: 0 | K38: 0 | L38: 3 | M38: 2 | N38: 1 | O38: 2 | P38: 1 | Q38: 1 | R38: 2 | S38: 1 | T38: 0 | U38: 0 | V38: 2 | W38: 3 | X38: 0 | Y38: 2 | Z38: 1 | AA38: 0 | AB38: 2 | AC38: 2 | AD38: 3 | AE38: 1 | AF38: 1 | AG38: =SUM(C38:AF38) -> 44 | AH38: Cần động viên
A39: 37 | B39: Lý Thị AL | C39: 2 | D39: 2 | E39: 1 | F39: 2 | G39: 3 | H39: 2 | I39: 2 | J39: 0 | K39: 3 | L39: 0 | M39: 1 | N39: 1 | O39: 3 | P39: 2 | Q39: 0 | R39: 3 | S39: 0 | T39: 2 | U39: 0 | V39: 3 | W39: 2 | X39: 2 | Y39: 3 | Z39: 2 | AA39: 0 | AB39: 1 | AC39: 3 | AD39: 0 | AE39: 2 | AF39: 1 | AG39: =SUM(C39:AF39) -> 48 | AH39: Cần chú ý
A40: 38 | B40: Phan Văn AM | C40: 0 | D40: 3 | E40: 2 | F40: 3 | G40: 0 | H40: 1 | I40: 0 | J40: 0 | K40: 2 | L40: 3 | M40: 0 | N40: 0 | O40: 1 | P40: 1 | Q40: 3 | R40: 3 | S40: 2 | T40: 3 | U40: 1 | V40: 3 | W40: 0 | X40: 3 | Y40: 3 | Z40: 2 | AA40: 0 | AB40: 2 | AC40: 1 | AD40: 3 | AE40: 3 | AF40: 1 | AG40: =SUM(C40:AF40) -> 49
...

Sheet Tổng hợp Tháng
A1: BẢNG TỔNG HỢP THÁNG - LỚP 10A1 - THÁNG 3/2026
A2: Xếp hạng | B2: Họ và Tên | C2: Tổng Ngôi sao | D2: Trung bình/Ngày | E2: Số ngày đạt ≥5 sao | F2: Nhóm Tầng | G2: Hành động | H2: Level | I2: Cảnh báo
A3: =ROW()-2 -> 1 | B3: ='Theo dõi Ngày'!B3 -> Lê Văn C | C3: ='Theo dõi Ngày'!AG3 -> 165 | D3: =C3/30 -> 5.5 | E3: =COUNTIF('Theo dõi Ngày'!C3:AF3,">=5") -> 16 | F3: =IF(D3>=4,"Tầng 1",IF(D3>=2,"Tầng 2","Tầng 3")) -> Tầng 1 | G3: =IF(F3="Tầng 1","Khen thưởng",IF(F3="Tầng 2","Can thiệp nhóm","Can thiệp cá nhân")) -> Khen thưởng | H3: =IF(C3>=151,"Huyền thoại",IF(C3>=101,"Anh hùng",IF(C3>=51,"Chiến binh","Người mới"))) -> Huyền thoại | I3: =IF(D3<2,"⚠️ CẦN CAN THIỆP NGAY","")
A4: =ROW()-2 -> 2 | B4: ='Theo dõi Ngày'!B4 -> Nguyễn Văn A | C4: ='Theo dõi Ngày'!AG4 -> 151 | D4: =C4/30 -> 5.0333333 | E4: =COUNTIF('Theo dõi Ngày'!C4:AF4,">=5") -> 19 | F4: =IF(D4>=4,"Tầng 1",IF(D4>=2,"Tầng 2","Tầng 3")) -> Tầng 1 | G4: =IF(F4="Tầng 1","Khen thưởng",IF(F4="Tầng 2","Can thiệp nhóm","Can thiệp cá nhân")) -> Khen thưởng | H4: =IF(C4>=151,"Huyền thoại",IF(C4>=101,"Anh hùng",IF(C4>=51,"Chiến binh","Người mới"))) -> Huyền thoại | I4: =IF(D4<2,"⚠️ CẦN CAN THIỆP NGAY","")
A5: =ROW()-2 -> 3 | B5: ='Theo dõi Ngày'!B5 -> Trần Minh D | C5: ='Theo dõi Ngày'!AG5 -> 167 | D5: =C5/30 -> 5.5666667 | E5: =COUNTIF('Theo dõi Ngày'!C5:AF5,">=5") -> 20 | F5: =IF(D5>=4,"Tầng 1",IF(D5>=2,"Tầng 2","Tầng 3")) -> Tầng 1 | G5: =IF(F5="Tầng 1","Khen thưởng",IF(F5="Tầng 2","Can thiệp nhóm","Can thiệp cá nhân")) -> Khen thưởng | H5: =IF(C5>=151,"Huyền thoại",IF(C5>=101,"Anh hùng",IF(C5>=51,"Chiến binh","Người mới"))) -> Huyền thoại | I5: =IF(D5<2,"⚠️ CẦN CAN THIỆP NGAY","")
A6: =ROW()-2 -> 4 | B6: ='Theo dõi Ngày'!B6 -> Phạm Thị E | C6: ='Theo dõi Ngày'!AG6 -> 169 | D6: =C6/30 -> 5.6333333 | E6: =COUNTIF('Theo dõi Ngày'!C6:AF6,">=5") -> 20 | F6: =IF(D6>=4,"Tầng 1",IF(D6>=2,"Tầng 2","Tầng 3")) -> Tầng 1 | G6: =IF(F6="Tầng 1","Khen thưởng",IF(F6="Tầng 2","Can thiệp nhóm","Can thiệp cá nhân")) -> Khen thưởng | H6: =IF(C6>=151,"Huyền thoại",IF(C6>=101,"Anh hùng",IF(C6>=51,"Chiến binh","Người mới"))) -> Huyền thoại | I6: =IF(D6<2,"⚠️ CẦN CAN THIỆP NGAY","")
A7: =ROW()-2 -> 5 | B7: ='Theo dõi Ngày'!B7 -> Hoàng Văn F | C7: ='Theo dõi Ngày'!AG7 -> 165 | D7: =C7/30 -> 5.5 | E7: =COUNTIF('Theo dõi Ngày'!C7:AF7,">=5") -> 19 | F7: =IF(D7>=4,"Tầng 1",IF(D7>=2,"Tầng 2","Tầng 3")) -> Tầng 1 | G7: =IF(F7="Tầng 1","Khen thưởng",IF(F7="Tầng 2","Can thiệp nhóm","Can thiệp cá nhân")) -> Khen thưởng | H7: =IF(C7>=151,"Huyền thoại",IF(C7>=101,"Anh hùng",IF(C7>=51,"Chiến binh","Người mới"))) -> Huyền thoại | I7: =IF(D7<2,"⚠️ CẦN CAN THIỆP NGAY","")
A8: =ROW()-2 -> 6 | B8: ='Theo dõi Ngày'!B8 -> Đỗ Thị G | C8: ='Theo dõi Ngày'!AG8 -> 124 | D8: =C8/30 -> 4.1333333 | E8: =COUNTIF('Theo dõi Ngày'!C8:AF8,">=5") -> 12 | F8: =IF(D8>=4,"Tầng 1",IF(D8>=2,"Tầng 2","Tầng 3")) -> Tầng 1 | G8: =IF(F8="Tầng 1","Khen thưởng",IF(F8="Tầng 2","Can thiệp nhóm","Can thiệp cá nhân")) -> Khen thưởng | H8: =IF(C8>=151,"Huyền thoại",IF(C8>=101,"Anh hùng",IF(C8>=51,"Chiến binh","Người mới"))) -> Anh hùng | I8: =IF(D8<2,"⚠️ CẦN CAN THIỆP NGAY","")
A9: =ROW()-2 -> 7 | B9: ='Theo dõi Ngày'!B9 -> Vũ Văn H | C9: ='Theo dõi Ngày'!AG9 -> 118 | D9: =C9/30 -> 3.9333333 | E9: =COUNTIF('Theo dõi Ngày'!C9:AF9,">=5") -> 11 | F9: =IF(D9>=4,"Tầng 1",IF(D9>=2,"Tầng 2","Tầng 3")) -> Tầng 2 | G9: =IF(F9="Tầng 1","Khen thưởng",IF(F9="Tầng 2","Can thiệp nhóm","Can thiệp cá nhân")) -> Can thiệp nhóm | H9: =IF(C9>=151,"Huyền thoại",IF(C9>=101,"Anh hùng",IF(C9>=51,"Chiến binh","Người mới"))) -> Anh hùng | I9: =IF(D9<2,"⚠️ CẦN CAN THIỆP NGAY","")
A10: =ROW()-2 -> 8 | B10: ='Theo dõi Ngày'!B10 -> Bùi Thị I | C10: ='Theo dõi Ngày'!AG10 -> 112 | D10: =C10/30 -> 3.7333333 | E10: =COUNTIF('Theo dõi Ngày'!C10:AF10,">=5") -> 10 | F10: =IF(D10>=4,"Tầng 1",IF(D10>=2,"Tầng 2","Tầng 3")) -> Tầng 2 | G10: =IF(F10="Tầng 1","Khen thưởng",IF(F10="Tầng 2","Can thiệp nhóm","Can thiệp cá nhân")) -> Can thiệp nhóm | H10: =IF(C10>=151,"Huyền thoại",IF(C10>=101,"Anh hùng",IF(C10>=51,"Chiến binh","Người mới"))) -> Anh hùng | I10: =IF(D10<2,"⚠️ CẦN CAN THIỆP NGAY","")
A11: =ROW()-2 -> 9 | B11: ='Theo dõi Ngày'!B11 -> Ngô Văn K | C11: ='Theo dõi Ngày'!AG11 -> 111 | D11: =C11/30 -> 3.7 | E11: =COUNTIF('Theo dõi Ngày'!C11:AF11,">=5") -> 12 | F11: =IF(D11>=4,"Tầng 1",IF(D11>=2,"Tầng 2","Tầng 3")) -> Tầng 2 | G11: =IF(F11="Tầng 1","Khen thưởng",IF(F11="Tầng 2","Can thiệp nhóm","Can thiệp cá nhân")) -> Can thiệp nhóm | H11: =IF(C11>=151,"Huyền thoại",IF(C11>=101,"Anh hùng",IF(C11>=51,"Chiến binh","Người mới"))) -> Anh hùng | I11: =IF(D11<2,"⚠️ CẦN CAN THIỆP NGAY","")
A12: =ROW()-2 -> 10 | B12: ='Theo dõi Ngày'!B12 -> Đặng Thị L | C12: ='Theo dõi Ngày'!AG12 -> 116 | D12: =C12/30 -> 3.8666667 | E12: =COUNTIF('Theo dõi Ngày'!C12:AF12,">=5") -> 13 | F12: =IF(D12>=4,"Tầng 1",IF(D12>=2,"Tầng 2","Tầng 3")) -> Tầng 2 | G12: =IF(F12="Tầng 1","Khen thưởng",IF(F12="Tầng 2","Can thiệp nhóm","Can thiệp cá nhân")) -> Can thiệp nhóm | H12: =IF(C12>=151,"Huyền thoại",IF(C12>=101,"Anh hùng",IF(C12>=51,"Chiến binh","Người mới"))) -> Anh hùng | I12: =IF(D12<2,"⚠️ CẦN CAN THIỆP NGAY","")
A13: =ROW()-2 -> 11 | B13: ='Theo dõi Ngày'!B13 -> Lý Văn M | C13: ='Theo dõi Ngày'!AG13 -> 123 | D13: =C13/30 -> 4.1 | E13: =COUNTIF('Theo dõi Ngày'!C13:AF13,">=5") -> 15 | F13: =IF(D13>=4,"Tầng 1",IF(D13>=2,"Tầng 2","Tầng 3")) -> Tầng 1 | G13: =IF(F13="Tầng 1","Khen thưởng",IF(F13="Tầng 2","Can thiệp nhóm","Can thiệp cá nhân")) -> Khen thưởng | H13: =IF(C13>=151,"Huyền thoại",IF(C13>=101,"Anh hùng",IF(C13>=51,"Chiến binh","Người mới"))) -> Anh hùng | I13: =IF(D13<2,"⚠️ CẦN CAN THIỆP NGAY","")
A14: =ROW()-2 -> 12 | B14: ='Theo dõi Ngày'!B14 -> Phan Thị N | C14: ='Theo dõi Ngày'!AG14 -> 115 | D14: =C14/30 -> 3.8333333 | E14: =COUNTIF('Theo dõi Ngày'!C14:AF14,">=5") -> 8 | F14: =IF(D14>=4,"Tầng 1",IF(D14>=2,"Tầng 2","Tầng 3")) -> Tầng 2 | G14: =IF(F14="Tầng 1","Khen thưởng",IF(F14="Tầng 2","Can thiệp nhóm","Can thiệp cá nhân")) -> Can thiệp nhóm | H14: =IF(C14>=151,"Huyền thoại",IF(C14>=101,"Anh hùng",IF(C14>=51,"Chiến binh","Người mới"))) -> Anh hùng | I14: =IF(D14<2,"⚠️ CẦN CAN THIỆP NGAY","")
... A42: =ROW()-2 -> 40 | B42: ='Theo dõi Ngày'!B42 -> Hồ Văn AO | C42: ='Theo dõi Ngày'!AG42 -> 13 | D42: =C42/30 -> 0.43333333 | E42: =COUNTIF('Theo dõi Ngày'!C42:AF42,">=5") -> 0 | F42: =IF(D42>=4,"Tầng 1",IF(D42>=2,"Tầng 2","Tầng 3")) -> Tầng 3 | G42: =IF(F42="Tầng 1","Khen thưởng",IF(F42="Tầng 2","Can thiệp nhóm","Can thiệp cá nhân")) -> Can thiệp cá nhân | H42: =IF(C42>=151,"Huyền thoại",IF(C42>=101,"Anh hùng",IF(C42>=51,"Chiến binh","Người mới"))) -> Người mới | I42: =IF(D42<2,"⚠️ CẦN CAN THIỆP NGAY","") -> ⚠️ CẦN CAN THIỆP NGAY
A45: THỐNG KÊ PHÂN BỔ TẦNG
A46: Tầng 1 (Tốt): | B46: =COUNTIF(F3:F42,"Tầng 1")&" em ("&TEXT(COUNTIF(F3:F42,"Tầng 1")*100/COUNTA(F3:F42),"0")&"%)" -> 14 em (35%)
A47: Tầng 2 (Cần hỗ trợ): | B47: =COUNTIF(F3:F42,"Tầng 2")&" em ("&TEXT(COUNTIF(F3:F42,"Tầng 2")*100/COUNTA(F3:F42),"0")&"%)" -> 21 em (53%)
A48: Tầng 3 (Can thiệp): | B48: =COUNTIF(F3:F42,"Tầng 3")&" em ("&TEXT(COUNTIF(F3:F42,"Tầng 3")*100/COUNTA(F3:F42),"0")&"%)" -> 5 em (13%)
A50: Tầng 1 | B50: =COUNTIF(F3:F42,"Tầng 1") -> 14
A51: Tầng 2 | B51: =COUNTIF(F3:F42,"Tầng 2") -> 21
A52: Tầng 3 | B52: =COUNTIF(F3:F42,"Tầng 3") -> 5

Sheet Danh mục Hành vi
A1: DANH MỤC HÀNH VI MONG ĐỢI - HỆ THỐNG PBIS
A2: Mã HV | B2: Hành vi Mong đợi | C2: Định nghĩa Cụ thể | D2: Ví dụ Quan sát được | E2: Số Ngôi sao
A3: HV01 | B3: Tham gia Phát biểu | C3: Giơ tay và trả lời câu hỏi của giáo viên, không cần đúng 100% | D3: Em giơ tay cao, nói rõ ràng: "Thưa thầy, em nghĩ đáp án là B vì..." | E3: 1 sao/lần
A4: HV02 | B4: Giúp đỡ Bạn bè | C4: Chủ động hỗ trợ bạn học bài, giải thích kiến thức, cho mượn đồ dùng | D4: Em A giải thích bài toán cho em B trong giờ tự học | E4: 2 sao/lần
A5: HV03 | B5: Hoàn thành Đúng hạn | C5: Nộp bài tập, đồ án đúng hoặc trước deadline | D5: Nộp bài tập Toán trước 7h sáng thứ 2 | E5: 1 sao/bài
A6: HV04 | B6: Giữ gìn Vệ sinh | C6: Nhặt rác không phải của mình, lau bảng, sắp xếp bàn ghế | D6: Em C nhặt giấy vụn dưới sàn sau giờ ra chơi | E6: 2 sao/lần
A7: HV05 | B7: Đến lớp Đúng giờ | C7: Có mặt trong lớp trước 7h00 sáng, đồng phục gọn gàng | D7: Em D đến lớp lúc 6h55, áo sơ mi là phẳng | E7: 1 sao/ngày
A8: HV06 | B8: Tôn trọng Ý kiến | C8: Lắng nghe bạn nói hết, không ngắt lời, phản hồi lịch sự | D8: "Em đồng ý với ý kiến của bạn E, và em muốn bổ sung thêm..." | E8: 2 sao/lần
A9: HV07 | B9: Sáng tạo Giải pháp | C9: Đưa ra ý tưởng mới trong hoạt động nhóm, dự án lớp | D9: Em F đề xuất dùng Canva để làm poster thay vì vẽ tay | E9: 3 sao/lần
A10: HV08 | B10: Tự học Chủ động | C10: Tự tìm tài liệu, hỏi thêm giáo viên ngoài giờ, làm bài nâng cao | D10: Em G hỏi thầy về bài toán Olympic sau giờ tan trường | E10: 3 sao/lần
A13: HƯỚNG DẪN SỬ DỤNG
A14: 📌 In ra A4: Dán lên tường lớp học, mọi người đều thấy
A15: 📌 Chia sẻ cho phụ huynh: Gửi qua Zalo nhóm lớp
A16: 📌 Cập nhật định kỳ: Mỗi tháng bổ sung thêm 1-2 hành vi mới dựa trên nhu cầu lớp

Sheet Can thiệp Tầng 2-3
A1: THEO DÕI CAN THIỆP TẦNG 2-3
A3: BẢNG CAN THIỆP TẦNG 2 (Nhóm nhỏ)
A4: Họ và Tên | B4: Vấn đề Chính | C4: Can thiệp Áp dụng | D4: Người Phụ trách | E4: Ngày Bắt đầu | F4: Ngày Đánh giá | G4: Tiến triển | H4: Trạng thái
A5: Trần Thị B | B5: Hay đến muộn, quên đồ | C5: Check-in buổi sáng + Checklist | D5: GVCN | E5: 01/03/2026 | F5: 15/03/2026 | G5: Giảm từ 8 lần/tháng → 3 lần/tháng | H5: Đang cải thiện
A6: Lê Văn H | B6: Ít tham gia phát biểu | C6: Nhóm kỹ năng giao tiếp (5 em) | D6: GV Văn | E6: 05/03/2026 | F6: 20/03/2026 | G6: Tăng từ 0 lần/tuần → 2 lần/tuần | H6: Đang cải thiện
A12: BẢNG CAN THIỆP TẦNG 3 (Cá nhân)
A13: Họ và Tên | B13: Đánh giá Chức năng HV (FBA) | C13: Kế hoạch Can thiệp (BIP) | D13: Nhóm Hỗ trợ | E13: Tần suất Họp | F13: Kết quả Gần nhất
A14: Phạm Văn D | B14: Hành vi gây rối do thiếu sự chú ý, gia đình ít quan tâm | C14: - Góc yên tĩnh trong lớp - 15 phút tư vấn/ngày - Gặp phụ huynh 1 lần/tuần | D14: GVCN + Tâm lý + Phụ huynh | E14: 1 lần/2 tuần | F14: Giảm 60% hành vi gây rối sau 1 tháng

Sheet Phần thưởng & Đổi điểm
A1: MENU PHẦN THƯỞNG & ĐỔI ĐIỂM
A3: BẢNG MENU PHẦN THƯỞNG
A4: Mã PT | B4: Tên Phần thưởng | C4: Số Ngôi sao Cần | D4: Mô tả Chi tiết | E4: Số lượng Còn | F4: Hạn sử dụng
A5: PT01 | B5: Chọn chỗ ngồi 1 tuần | C5: 10 | D5: Được chọn vị trí ngồi yêu thích trong 1 tuần | E5: Không giới hạn | F5: Đổi trước thứ 6 hàng tuần
A6: PT02 | B6: Miễn 1 bài tập về nhà | C6: 20 | D6: Được miễn làm 1 bài tập bất kỳ (trừ bài kiểm tra) | E6: 5 suất/tháng | F6: Thông báo trước 1 ngày
A7: PT03 | B7: Ăn trưa cùng GVCN | C7: 50 | D7: Ăn trưa và trò chuyện với thầy/cô tại căng tin | E7: 2 suất/tháng | F7: Đặt trước 3 ngày
A8: PT04 | B8: Thẻ "Ra khỏi lớp 5 phút" | C8: 30 | D8: Được phép ra khỏi lớp 5 phút khi cảm thấy căng thẳng | E8: 10 suất/tháng | F8: Sử dụng ngay
A9: PT05 | B9: Voucher nhà sách 50k | C9: 100 | D9: Phiếu mua sách tại nhà sách Fahasa | E9: 3 suất/tháng | F9: Hết tháng hết hạn
A10: PT06 | B10: Được dẫn hoạt động lớp | C10: 80 | D10: Làm MC buổi sinh hoạt lớp hoặc dẫn trò chơi | E10: 1 suất/tháng | F10: Đăng ký trước 1 tuần
A13: LỊCH SỬ ĐỔI ĐIỂM
A14: Ngày Đổi | B14: Họ và Tên | C14: Mã PT | D14: Tên Phần thưởng | E14: Số Sao Trừ | F14: Số Sao Còn lại | G14: Người Duyệt
A15: 05/03/2026 | B15: Lê Văn C | C15: PT01 | D15: Chọn chỗ ngồi 1 tuần | E15: -10 | F15: =VLOOKUP(B15,'Tổng hợp Tháng'!B:C,2,FALSE())+E15 -> 155 | G15: GVCN
A16: 10/03/2026 | B16: Nguyễn Văn A | C16: PT02 | D16: Miễn 1 bài tập về nhà | E16: -20 | F16: =VLOOKUP(B16,'Tổng hợp Tháng'!B:C,2,FALSE())+E16 -> 131 | G16: GVCN

Sheet Biểu đồ & Báo cáo
A1: BIỂU ĐỒ & BÁO CÁO PBIS - LỚP 10A1 - THÁNG 3/2026
A3: Biểu đồ 1: Xu hướng Ngôi sao Cả lớp Theo Tuần
A4: Tuần | B4: Tổng Ngôi sao
A5: Tuần 1 | B5: =SUM('Theo dõi Ngày'!C3:I42) -> 988
A6: Tuần 2 | B6: =SUM('Theo dõi Ngày'!J3:P42) -> 952
A7: Tuần 3 | B7: =SUM('Theo dõi Ngày'!Q3:W42) -> 945
A8: Tuần 4 | B8: =SUM('Theo dõi Ngày'!X3:AF42) -> 1310
A12: Biểu đồ 2: Top 10 Học sinh Xuất sắc
A13: Họ và Tên | B13: Tổng Ngôi sao
A14: ='Tổng hợp Tháng'!B3 -> Lê Văn C | B14: ='Tổng hợp Tháng'!C3 -> 165
A15: ='Tổng hợp Tháng'!B4 -> Nguyễn Văn A | B15: ='Tổng hợp Tháng'!C4 -> 151
A16: ='Tổng hợp Tháng'!B5 -> Trần Minh D | B16: ='Tổng hợp Tháng'!C5 -> 167
A17: ='Tổng hợp Tháng'!B6 -> Phạm Thị E | B17: ='Tổng hợp Tháng'!C6 -> 169
A18: ='Tổng hợp Tháng'!B7 -> Hoàng Văn F | B18: ='Tổng hợp Tháng'!C7 -> 165
A19: ='Tổng hợp Tháng'!B8 -> Đỗ Thị G | B19: ='Tổng hợp Tháng'!C8 -> 124
A20: ='Tổng hợp Tháng'!B9 -> Vũ Văn H | B20: ='Tổng hợp Tháng'!C9 -> 118
A21: ='Tổng hợp Tháng'!B10 -> Bùi Thị I | B21: ='Tổng hợp Tháng'!C10 -> 112
A22: ='Tổng hợp Tháng'!B11 -> Ngô Văn K | B22: ='Tổng hợp Tháng'!C11 -> 111
A23: ='Tổng hợp Tháng'!B12 -> Đặng Thị L | B23: ='Tổng hợp Tháng'!C12 -> 116
A30: BÁO CÁO TỰ ĐỘNG - THÁNG 3/2026 - LỚP 10A1
A32: 📊 THỐNG KÊ TỔNG QUAN
A33: Tổng ngôi sao cả lớp: | B33: =SUM('Tổng hợp Tháng'!C:C) -> 4195
A34: Trung bình/học sinh: | B34: =AVERAGE('Tổng hợp Tháng'!C3:C42) -> 104.875
A35: HS đạt ≥100 sao: | B35: =COUNTIF('Tổng hợp Tháng'!C:C,">=100") -> 26
A37: 🎯 PHÂN BỔ TẦNG
A38: Tầng 1 (Tốt): | B38: =COUNTIF('Tổng hợp Tháng'!F:F,"Tầng 1")&" em" -> 14 em
A39: Tầng 2 (Cần hỗ trợ): | B39: =COUNTIF('Tổng hợp Tháng'!F:F,"Tầng 2")&" em" -> 21 em
A40: Tầng 3 (Can thiệp): | B40: =COUNTIF('Tổng hợp Tháng'!F:F,"Tầng 3")&" em" -> 5 em
A42: ⚠️ CẦN CHÚ Ý
A43: HS cần can thiệp Tầng 2: | B43: =COUNTIF('Tổng hợp Tháng'!F:F,"Tầng 2")&" em" -> 21 em
A44: HS cần can thiệp Tầng 3: | B44: =COUNTIF('Tổng hợp Tháng'!F:F,"Tầng 3")&" em" -> 5 em
